2021-07-11 04:25:37,952 -  nornir.core -     INFO -        run() - Running task 'netmiko_send_command' with args {'command_string': 'sho ip ospf nei'} on 8 hosts
2021-07-11 04:25:50,265 -  nornir.core -     INFO -        run() - Running task 'napalm_get' with args {'getters': ['facts', 'interfaces', 'arp_table']} on 8 hosts
2021-07-11 04:44:17,604 -  nornir.core -     INFO -        run() - Running task 'napalm_get' with args {'getters': ['facts', 'interfaces', 'arp_table']} on 8 hosts
2021-07-11 04:48:26,455 -  nornir.core -     INFO -        run() - Running task 'napalm_get' with args {'getters': ['get_interfaces_ip']} on 8 hosts
2021-07-11 04:51:02,041 -  nornir.core -     INFO -        run() - Running task 'napalm_get' with args {'getters': ['facts', 'interfaces', 'arp_table']} on 8 hosts
2021-07-11 05:01:56,468 -  nornir.core -     INFO -        run() - Running task 'netmiko_send_command' with args {'command_string': 'show version'} on 8 hosts
2021-07-11 05:01:57,368 -  nornir.core -     INFO -        run() - Running task 'netmiko_send_command' with args {'command_string': ' sho ip int br'} on 8 hosts
2021-07-11 05:02:36,844 -  nornir.core -     INFO -        run() - Running task 'netmiko_send_command' with args {'command_string': 'show version'} on 8 hosts
2021-07-11 05:02:37,752 -  nornir.core -     INFO -        run() - Running task 'netmiko_send_command' with args {'command_string': ' show ip int br'} on 8 hosts
2021-07-12 01:16:32,449 -  nornir.core -     INFO -        run() - Running task 'napalm_get' with args {'getters': ['facts', 'interfaces', 'arp_table']} on 8 hosts
2021-07-12 01:45:18,733 -  nornir.core -     INFO -        run() - Running task 'napalm_get' with args {'getters': ['facts', 'interfaces']} on 8 hosts
2021-07-12 02:03:27,175 -  nornir.core -     INFO -        run() - Running task 'napalm_get' with args {'getters': ['protocols']} on 8 hosts
2021-07-12 02:03:27,185 - nornir.core.task -    ERROR -      start() - Host 'R1': task 'napalm_get' failed with traceback:
Traceback (most recent call last):
  File "/home/tomw/.local/lib/python3.8/site-packages/nornir/core/task.py", line 99, in start
    r = self.task(self, **self.params)
  File "/home/tomw/.local/lib/python3.8/site-packages/nornir_napalm/plugins/tasks/napalm_get.py", line 43, in napalm_get
    method = getattr(device, getter)
AttributeError: 'IOSDriver' object has no attribute 'get_protocols'

2021-07-12 02:03:27,186 - nornir.core.task -    ERROR -      start() - Host 'R2': task 'napalm_get' failed with traceback:
Traceback (most recent call last):
  File "/home/tomw/.local/lib/python3.8/site-packages/nornir/core/task.py", line 99, in start
    r = self.task(self, **self.params)
  File "/home/tomw/.local/lib/python3.8/site-packages/nornir_napalm/plugins/tasks/napalm_get.py", line 43, in napalm_get
    method = getattr(device, getter)
AttributeError: 'IOSDriver' object has no attribute 'get_protocols'

2021-07-12 02:03:27,187 - nornir.core.task -    ERROR -      start() - Host 'R5': task 'napalm_get' failed with traceback:
Traceback (most recent call last):
  File "/home/tomw/.local/lib/python3.8/site-packages/nornir/core/task.py", line 99, in start
    r = self.task(self, **self.params)
  File "/home/tomw/.local/lib/python3.8/site-packages/nornir_napalm/plugins/tasks/napalm_get.py", line 43, in napalm_get
    method = getattr(device, getter)
AttributeError: 'IOSDriver' object has no attribute 'get_protocols'

2021-07-12 02:03:27,189 - nornir.core.task -    ERROR -      start() - Host 'R4': task 'napalm_get' failed with traceback:
Traceback (most recent call last):
  File "/home/tomw/.local/lib/python3.8/site-packages/nornir/core/task.py", line 99, in start
    r = self.task(self, **self.params)
  File "/home/tomw/.local/lib/python3.8/site-packages/nornir_napalm/plugins/tasks/napalm_get.py", line 43, in napalm_get
    method = getattr(device, getter)
AttributeError: 'IOSDriver' object has no attribute 'get_protocols'

2021-07-12 02:03:27,189 - nornir.core.task -    ERROR -      start() - Host 'R6': task 'napalm_get' failed with traceback:
Traceback (most recent call last):
  File "/home/tomw/.local/lib/python3.8/site-packages/nornir/core/task.py", line 99, in start
    r = self.task(self, **self.params)
  File "/home/tomw/.local/lib/python3.8/site-packages/nornir_napalm/plugins/tasks/napalm_get.py", line 43, in napalm_get
    method = getattr(device, getter)
AttributeError: 'IOSDriver' object has no attribute 'get_protocols'

2021-07-12 02:03:27,190 - nornir.core.task -    ERROR -      start() - Host 'R3': task 'napalm_get' failed with traceback:
Traceback (most recent call last):
  File "/home/tomw/.local/lib/python3.8/site-packages/nornir/core/task.py", line 99, in start
    r = self.task(self, **self.params)
  File "/home/tomw/.local/lib/python3.8/site-packages/nornir_napalm/plugins/tasks/napalm_get.py", line 43, in napalm_get
    method = getattr(device, getter)
AttributeError: 'IOSDriver' object has no attribute 'get_protocols'

2021-07-12 02:03:27,192 - nornir.core.task -    ERROR -      start() - Host 'R7': task 'napalm_get' failed with traceback:
Traceback (most recent call last):
  File "/home/tomw/.local/lib/python3.8/site-packages/nornir/core/task.py", line 99, in start
    r = self.task(self, **self.params)
  File "/home/tomw/.local/lib/python3.8/site-packages/nornir_napalm/plugins/tasks/napalm_get.py", line 43, in napalm_get
    method = getattr(device, getter)
AttributeError: 'IOSDriver' object has no attribute 'get_protocols'

2021-07-12 02:03:27,193 - nornir.core.task -    ERROR -      start() - Host 'R8': task 'napalm_get' failed with traceback:
Traceback (most recent call last):
  File "/home/tomw/.local/lib/python3.8/site-packages/nornir/core/task.py", line 99, in start
    r = self.task(self, **self.params)
  File "/home/tomw/.local/lib/python3.8/site-packages/nornir_napalm/plugins/tasks/napalm_get.py", line 43, in napalm_get
    method = getattr(device, getter)
AttributeError: 'IOSDriver' object has no attribute 'get_protocols'

2021-07-12 02:03:33,417 -  nornir.core -     INFO -        run() - Running task 'napalm_get' with args {'getters': ['protocols']} on 8 hosts
2021-07-12 02:06:33,369 -  nornir.core -     INFO -        run() - Running task 'napalm_get' with args {'getters': ['ospf']} on 8 hosts
2021-07-12 02:06:48,863 -  nornir.core -     INFO -        run() - Running task 'napalm_get' with args {'getters': ['route']} on 8 hosts
2021-07-12 02:14:50,102 -  nornir.core -     INFO -        run() - Running task 'napalm_get' with args {'getters': ['interfaces']} on 8 hosts
2021-07-12 02:15:23,528 -  nornir.core -     INFO -        run() - Running task 'napalm_get' with args {'getters': ['facts', 'interfaces']} on 8 hosts
2021-07-12 02:15:53,770 -  nornir.core -     INFO -        run() - Running task 'napalm_get' with args {'getters': ['facts', 'interfaces']} on 8 hosts
2021-07-12 02:16:15,146 -  nornir.core -     INFO -        run() - Running task 'napalm_get' with args {'getters': ['route']} on 8 hosts
2021-07-12 02:16:15,852 - nornir.core.task -    ERROR -      start() - Host 'R7': task 'napalm_get' failed with traceback:
Traceback (most recent call last):
  File "/home/tomw/.local/lib/python3.8/site-packages/nornir/core/task.py", line 99, in start
    r = self.task(self, **self.params)
  File "/home/tomw/.local/lib/python3.8/site-packages/nornir_napalm/plugins/tasks/napalm_get.py", line 43, in napalm_get
    method = getattr(device, getter)
AttributeError: 'IOSDriver' object has no attribute 'get_route'

2021-07-12 02:16:15,853 - nornir.core.task -    ERROR -      start() - Host 'R8': task 'napalm_get' failed with traceback:
Traceback (most recent call last):
  File "/home/tomw/.local/lib/python3.8/site-packages/nornir/core/task.py", line 99, in start
    r = self.task(self, **self.params)
  File "/home/tomw/.local/lib/python3.8/site-packages/nornir_napalm/plugins/tasks/napalm_get.py", line 43, in napalm_get
    method = getattr(device, getter)
AttributeError: 'IOSDriver' object has no attribute 'get_route'

2021-07-12 02:16:15,857 - nornir.core.task -    ERROR -      start() - Host 'R3': task 'napalm_get' failed with traceback:
Traceback (most recent call last):
  File "/home/tomw/.local/lib/python3.8/site-packages/nornir/core/task.py", line 99, in start
    r = self.task(self, **self.params)
  File "/home/tomw/.local/lib/python3.8/site-packages/nornir_napalm/plugins/tasks/napalm_get.py", line 43, in napalm_get
    method = getattr(device, getter)
AttributeError: 'IOSDriver' object has no attribute 'get_route'

2021-07-12 02:16:15,860 - nornir.core.task -    ERROR -      start() - Host 'R1': task 'napalm_get' failed with traceback:
Traceback (most recent call last):
  File "/home/tomw/.local/lib/python3.8/site-packages/nornir/core/task.py", line 99, in start
    r = self.task(self, **self.params)
  File "/home/tomw/.local/lib/python3.8/site-packages/nornir_napalm/plugins/tasks/napalm_get.py", line 43, in napalm_get
    method = getattr(device, getter)
AttributeError: 'IOSDriver' object has no attribute 'get_route'

2021-07-12 02:16:15,871 - nornir.core.task -    ERROR -      start() - Host 'R2': task 'napalm_get' failed with traceback:
Traceback (most recent call last):
  File "/home/tomw/.local/lib/python3.8/site-packages/nornir/core/task.py", line 99, in start
    r = self.task(self, **self.params)
  File "/home/tomw/.local/lib/python3.8/site-packages/nornir_napalm/plugins/tasks/napalm_get.py", line 43, in napalm_get
    method = getattr(device, getter)
AttributeError: 'IOSDriver' object has no attribute 'get_route'

2021-07-12 02:16:15,882 - nornir.core.task -    ERROR -      start() - Host 'R5': task 'napalm_get' failed with traceback:
Traceback (most recent call last):
  File "/home/tomw/.local/lib/python3.8/site-packages/nornir/core/task.py", line 99, in start
    r = self.task(self, **self.params)
  File "/home/tomw/.local/lib/python3.8/site-packages/nornir_napalm/plugins/tasks/napalm_get.py", line 43, in napalm_get
    method = getattr(device, getter)
AttributeError: 'IOSDriver' object has no attribute 'get_route'

2021-07-12 02:16:15,883 - nornir.core.task -    ERROR -      start() - Host 'R6': task 'napalm_get' failed with traceback:
Traceback (most recent call last):
  File "/home/tomw/.local/lib/python3.8/site-packages/nornir/core/task.py", line 99, in start
    r = self.task(self, **self.params)
  File "/home/tomw/.local/lib/python3.8/site-packages/nornir_napalm/plugins/tasks/napalm_get.py", line 43, in napalm_get
    method = getattr(device, getter)
AttributeError: 'IOSDriver' object has no attribute 'get_route'

2021-07-12 02:16:15,899 - nornir.core.task -    ERROR -      start() - Host 'R4': task 'napalm_get' failed with traceback:
Traceback (most recent call last):
  File "/home/tomw/.local/lib/python3.8/site-packages/nornir/core/task.py", line 99, in start
    r = self.task(self, **self.params)
  File "/home/tomw/.local/lib/python3.8/site-packages/nornir_napalm/plugins/tasks/napalm_get.py", line 43, in napalm_get
    method = getattr(device, getter)
AttributeError: 'IOSDriver' object has no attribute 'get_route'

2021-07-12 02:23:02,383 -  nornir.core -     INFO -        run() - Running task 'napalm_get' with args {'getters': ['ospf']} on 8 hosts
2021-07-12 02:23:02,938 - nornir.core.task -    ERROR -      start() - Host 'R7': task 'napalm_get' failed with traceback:
Traceback (most recent call last):
  File "/home/tomw/.local/lib/python3.8/site-packages/nornir/core/task.py", line 99, in start
    r = self.task(self, **self.params)
  File "/home/tomw/.local/lib/python3.8/site-packages/nornir_napalm/plugins/tasks/napalm_get.py", line 43, in napalm_get
    method = getattr(device, getter)
AttributeError: 'IOSDriver' object has no attribute 'get_ospf'

2021-07-12 02:23:02,954 - nornir.core.task -    ERROR -      start() - Host 'R4': task 'napalm_get' failed with traceback:
Traceback (most recent call last):
  File "/home/tomw/.local/lib/python3.8/site-packages/nornir/core/task.py", line 99, in start
    r = self.task(self, **self.params)
  File "/home/tomw/.local/lib/python3.8/site-packages/nornir_napalm/plugins/tasks/napalm_get.py", line 43, in napalm_get
    method = getattr(device, getter)
AttributeError: 'IOSDriver' object has no attribute 'get_ospf'

2021-07-12 02:23:03,000 - nornir.core.task -    ERROR -      start() - Host 'R3': task 'napalm_get' failed with traceback:
Traceback (most recent call last):
  File "/home/tomw/.local/lib/python3.8/site-packages/nornir/core/task.py", line 99, in start
    r = self.task(self, **self.params)
  File "/home/tomw/.local/lib/python3.8/site-packages/nornir_napalm/plugins/tasks/napalm_get.py", line 43, in napalm_get
    method = getattr(device, getter)
AttributeError: 'IOSDriver' object has no attribute 'get_ospf'

2021-07-12 02:23:03,020 - nornir.core.task -    ERROR -      start() - Host 'R5': task 'napalm_get' failed with traceback:
Traceback (most recent call last):
  File "/home/tomw/.local/lib/python3.8/site-packages/nornir/core/task.py", line 99, in start
    r = self.task(self, **self.params)
  File "/home/tomw/.local/lib/python3.8/site-packages/nornir_napalm/plugins/tasks/napalm_get.py", line 43, in napalm_get
    method = getattr(device, getter)
AttributeError: 'IOSDriver' object has no attribute 'get_ospf'

2021-07-12 02:23:03,103 - nornir.core.task -    ERROR -      start() - Host 'R6': task 'napalm_get' failed with traceback:
Traceback (most recent call last):
  File "/home/tomw/.local/lib/python3.8/site-packages/nornir/core/task.py", line 99, in start
    r = self.task(self, **self.params)
  File "/home/tomw/.local/lib/python3.8/site-packages/nornir_napalm/plugins/tasks/napalm_get.py", line 43, in napalm_get
    method = getattr(device, getter)
AttributeError: 'IOSDriver' object has no attribute 'get_ospf'

2021-07-12 02:23:03,177 - nornir.core.task -    ERROR -      start() - Host 'R2': task 'napalm_get' failed with traceback:
Traceback (most recent call last):
  File "/home/tomw/.local/lib/python3.8/site-packages/nornir/core/task.py", line 99, in start
    r = self.task(self, **self.params)
  File "/home/tomw/.local/lib/python3.8/site-packages/nornir_napalm/plugins/tasks/napalm_get.py", line 43, in napalm_get
    method = getattr(device, getter)
AttributeError: 'IOSDriver' object has no attribute 'get_ospf'

2021-07-12 02:23:03,186 - nornir.core.task -    ERROR -      start() - Host 'R1': task 'napalm_get' failed with traceback:
Traceback (most recent call last):
  File "/home/tomw/.local/lib/python3.8/site-packages/nornir/core/task.py", line 99, in start
    r = self.task(self, **self.params)
  File "/home/tomw/.local/lib/python3.8/site-packages/nornir_napalm/plugins/tasks/napalm_get.py", line 43, in napalm_get
    method = getattr(device, getter)
AttributeError: 'IOSDriver' object has no attribute 'get_ospf'

2021-07-12 02:23:03,195 - nornir.core.task -    ERROR -      start() - Host 'R8': task 'napalm_get' failed with traceback:
Traceback (most recent call last):
  File "/home/tomw/.local/lib/python3.8/site-packages/nornir/core/task.py", line 99, in start
    r = self.task(self, **self.params)
  File "/home/tomw/.local/lib/python3.8/site-packages/nornir_napalm/plugins/tasks/napalm_get.py", line 43, in napalm_get
    method = getattr(device, getter)
AttributeError: 'IOSDriver' object has no attribute 'get_ospf'

2021-07-12 02:52:03,868 -  nornir.core -     INFO -        run() - Running task 'napalm_get' with args {'getters': ['ip']} on 8 hosts
2021-07-12 02:52:04,482 - nornir.core.task -    ERROR -      start() - Host 'R1': task 'napalm_get' failed with traceback:
Traceback (most recent call last):
  File "/home/tomw/.local/lib/python3.8/site-packages/nornir/core/task.py", line 99, in start
    r = self.task(self, **self.params)
  File "/home/tomw/.local/lib/python3.8/site-packages/nornir_napalm/plugins/tasks/napalm_get.py", line 43, in napalm_get
    method = getattr(device, getter)
AttributeError: 'IOSDriver' object has no attribute 'get_ip'

2021-07-12 02:52:04,596 - nornir.core.task -    ERROR -      start() - Host 'R7': task 'napalm_get' failed with traceback:
Traceback (most recent call last):
  File "/home/tomw/.local/lib/python3.8/site-packages/nornir/core/task.py", line 99, in start
    r = self.task(self, **self.params)
  File "/home/tomw/.local/lib/python3.8/site-packages/nornir_napalm/plugins/tasks/napalm_get.py", line 43, in napalm_get
    method = getattr(device, getter)
AttributeError: 'IOSDriver' object has no attribute 'get_ip'

2021-07-12 02:52:04,606 - nornir.core.task -    ERROR -      start() - Host 'R8': task 'napalm_get' failed with traceback:
Traceback (most recent call last):
  File "/home/tomw/.local/lib/python3.8/site-packages/nornir/core/task.py", line 99, in start
    r = self.task(self, **self.params)
  File "/home/tomw/.local/lib/python3.8/site-packages/nornir_napalm/plugins/tasks/napalm_get.py", line 43, in napalm_get
    method = getattr(device, getter)
AttributeError: 'IOSDriver' object has no attribute 'get_ip'

2021-07-12 02:52:04,620 - nornir.core.task -    ERROR -      start() - Host 'R3': task 'napalm_get' failed with traceback:
Traceback (most recent call last):
  File "/home/tomw/.local/lib/python3.8/site-packages/nornir/core/task.py", line 99, in start
    r = self.task(self, **self.params)
  File "/home/tomw/.local/lib/python3.8/site-packages/nornir_napalm/plugins/tasks/napalm_get.py", line 43, in napalm_get
    method = getattr(device, getter)
AttributeError: 'IOSDriver' object has no attribute 'get_ip'

2021-07-12 02:52:04,643 - nornir.core.task -    ERROR -      start() - Host 'R2': task 'napalm_get' failed with traceback:
Traceback (most recent call last):
  File "/home/tomw/.local/lib/python3.8/site-packages/nornir/core/task.py", line 99, in start
    r = self.task(self, **self.params)
  File "/home/tomw/.local/lib/python3.8/site-packages/nornir_napalm/plugins/tasks/napalm_get.py", line 43, in napalm_get
    method = getattr(device, getter)
AttributeError: 'IOSDriver' object has no attribute 'get_ip'

2021-07-12 02:52:04,645 - nornir.core.task -    ERROR -      start() - Host 'R5': task 'napalm_get' failed with traceback:
Traceback (most recent call last):
  File "/home/tomw/.local/lib/python3.8/site-packages/nornir/core/task.py", line 99, in start
    r = self.task(self, **self.params)
  File "/home/tomw/.local/lib/python3.8/site-packages/nornir_napalm/plugins/tasks/napalm_get.py", line 43, in napalm_get
    method = getattr(device, getter)
AttributeError: 'IOSDriver' object has no attribute 'get_ip'

2021-07-12 02:52:04,646 - nornir.core.task -    ERROR -      start() - Host 'R6': task 'napalm_get' failed with traceback:
Traceback (most recent call last):
  File "/home/tomw/.local/lib/python3.8/site-packages/nornir/core/task.py", line 99, in start
    r = self.task(self, **self.params)
  File "/home/tomw/.local/lib/python3.8/site-packages/nornir_napalm/plugins/tasks/napalm_get.py", line 43, in napalm_get
    method = getattr(device, getter)
AttributeError: 'IOSDriver' object has no attribute 'get_ip'

2021-07-12 02:52:04,650 - nornir.core.task -    ERROR -      start() - Host 'R4': task 'napalm_get' failed with traceback:
Traceback (most recent call last):
  File "/home/tomw/.local/lib/python3.8/site-packages/nornir/core/task.py", line 99, in start
    r = self.task(self, **self.params)
  File "/home/tomw/.local/lib/python3.8/site-packages/nornir_napalm/plugins/tasks/napalm_get.py", line 43, in napalm_get
    method = getattr(device, getter)
AttributeError: 'IOSDriver' object has no attribute 'get_ip'

2021-07-12 02:52:36,233 -  nornir.core -     INFO -        run() - Running task 'napalm_get' with args {'getters': ['interfaces']} on 8 hosts
2021-07-12 16:55:28,769 -  nornir.core -     INFO -        run() - Running task 'napalm_get' with args {'getters': ['facts', 'interfaces', 'arp_table']} on 8 hosts
2021-07-13 12:07:46,433 -  nornir.core -     INFO -        run() - Running task 'napalm_get' with args {'getters': ['facts', 'interfaces', 'arp_table']} on 8 hosts
2021-07-14 12:03:00,822 -  nornir.core -     INFO -        run() - Running task 'netmiko_send_command' with args {'command_string': 'wr'} on 8 hosts
2021-07-14 12:07:13,457 -  nornir.core -     INFO -        run() - Running task 'napalm_get' with args {'getters': ['facts', 'interfaces', 'arp_table']} on 8 hosts
2021-07-14 15:33:25,867 -  nornir.core -     INFO -        run() - Running task 'netmiko_send_command' with args {'command_string': 'sho ip int br'} on 8 hosts
2021-07-14 15:33:28,955 - nornir.core.task -    ERROR -      start() - Host 'R1': task 'netmiko_send_command' failed with traceback:
Traceback (most recent call last):
  File "/home/tomw/.local/lib/python3.8/site-packages/netmiko/base_connection.py", line 935, in establish_connection
    self.remote_conn_pre.connect(**ssh_connect_params)
  File "/home/tomw/.local/lib/python3.8/site-packages/paramiko/client.py", line 368, in connect
    raise NoValidConnectionsError(errors)
paramiko.ssh_exception.NoValidConnectionsError: [Errno None] Unable to connect to port 22 on 192.168.100.101

During handling of the above exception, another exception occurred:

Traceback (most recent call last):
  File "/home/tomw/.local/lib/python3.8/site-packages/nornir/core/task.py", line 99, in start
    r = self.task(self, **self.params)
  File "/home/tomw/.local/lib/python3.8/site-packages/nornir_netmiko/tasks/netmiko_send_command.py", line 26, in netmiko_send_command
    net_connect = task.host.get_connection(CONNECTION_NAME, task.nornir.config)
  File "/home/tomw/.local/lib/python3.8/site-packages/nornir/core/inventory.py", line 494, in get_connection
    self.open_connection(
  File "/home/tomw/.local/lib/python3.8/site-packages/nornir/core/inventory.py", line 546, in open_connection
    conn_obj.open(
  File "/home/tomw/.local/lib/python3.8/site-packages/nornir_netmiko/connections/netmiko.py", line 59, in open
    connection = ConnectHandler(**parameters)
  File "/home/tomw/.local/lib/python3.8/site-packages/netmiko/ssh_dispatcher.py", line 326, in ConnectHandler
    return ConnectionClass(*args, **kwargs)
  File "/home/tomw/.local/lib/python3.8/site-packages/netmiko/cisco/cisco_ios.py", line 17, in __init__
    return super().__init__(*args, **kwargs)
  File "/home/tomw/.local/lib/python3.8/site-packages/netmiko/base_connection.py", line 350, in __init__
    self._open()
  File "/home/tomw/.local/lib/python3.8/site-packages/netmiko/base_connection.py", line 355, in _open
    self.establish_connection()
  File "/home/tomw/.local/lib/python3.8/site-packages/netmiko/base_connection.py", line 957, in establish_connection
    raise NetmikoTimeoutException(msg)
netmiko.ssh_exception.NetmikoTimeoutException: TCP connection to device failed.

Common causes of this problem are:
1. Incorrect hostname or IP address.
2. Wrong TCP port.
3. Intermediate firewall blocking access.

Device settings: cisco_ios 192.168.100.101:22



2021-07-14 15:33:28,956 - nornir.core.task -    ERROR -      start() - Host 'R2': task 'netmiko_send_command' failed with traceback:
Traceback (most recent call last):
  File "/home/tomw/.local/lib/python3.8/site-packages/netmiko/base_connection.py", line 935, in establish_connection
    self.remote_conn_pre.connect(**ssh_connect_params)
  File "/home/tomw/.local/lib/python3.8/site-packages/paramiko/client.py", line 368, in connect
    raise NoValidConnectionsError(errors)
paramiko.ssh_exception.NoValidConnectionsError: [Errno None] Unable to connect to port 22 on 192.168.100.102

During handling of the above exception, another exception occurred:

Traceback (most recent call last):
  File "/home/tomw/.local/lib/python3.8/site-packages/nornir/core/task.py", line 99, in start
    r = self.task(self, **self.params)
  File "/home/tomw/.local/lib/python3.8/site-packages/nornir_netmiko/tasks/netmiko_send_command.py", line 26, in netmiko_send_command
    net_connect = task.host.get_connection(CONNECTION_NAME, task.nornir.config)
  File "/home/tomw/.local/lib/python3.8/site-packages/nornir/core/inventory.py", line 494, in get_connection
    self.open_connection(
  File "/home/tomw/.local/lib/python3.8/site-packages/nornir/core/inventory.py", line 546, in open_connection
    conn_obj.open(
  File "/home/tomw/.local/lib/python3.8/site-packages/nornir_netmiko/connections/netmiko.py", line 59, in open
    connection = ConnectHandler(**parameters)
  File "/home/tomw/.local/lib/python3.8/site-packages/netmiko/ssh_dispatcher.py", line 326, in ConnectHandler
    return ConnectionClass(*args, **kwargs)
  File "/home/tomw/.local/lib/python3.8/site-packages/netmiko/cisco/cisco_ios.py", line 17, in __init__
    return super().__init__(*args, **kwargs)
  File "/home/tomw/.local/lib/python3.8/site-packages/netmiko/base_connection.py", line 350, in __init__
    self._open()
  File "/home/tomw/.local/lib/python3.8/site-packages/netmiko/base_connection.py", line 355, in _open
    self.establish_connection()
  File "/home/tomw/.local/lib/python3.8/site-packages/netmiko/base_connection.py", line 957, in establish_connection
    raise NetmikoTimeoutException(msg)
netmiko.ssh_exception.NetmikoTimeoutException: TCP connection to device failed.

Common causes of this problem are:
1. Incorrect hostname or IP address.
2. Wrong TCP port.
3. Intermediate firewall blocking access.

Device settings: cisco_ios 192.168.100.102:22



2021-07-14 15:33:30,928 - nornir.core.task -    ERROR -      start() - Host 'R3': task 'netmiko_send_command' failed with traceback:
Traceback (most recent call last):
  File "/home/tomw/.local/lib/python3.8/site-packages/netmiko/base_connection.py", line 935, in establish_connection
    self.remote_conn_pre.connect(**ssh_connect_params)
  File "/home/tomw/.local/lib/python3.8/site-packages/paramiko/client.py", line 349, in connect
    retry_on_signal(lambda: sock.connect(addr))
  File "/home/tomw/.local/lib/python3.8/site-packages/paramiko/util.py", line 283, in retry_on_signal
    return function()
  File "/home/tomw/.local/lib/python3.8/site-packages/paramiko/client.py", line 349, in <lambda>
    retry_on_signal(lambda: sock.connect(addr))
socket.timeout: timed out

During handling of the above exception, another exception occurred:

Traceback (most recent call last):
  File "/home/tomw/.local/lib/python3.8/site-packages/nornir/core/task.py", line 99, in start
    r = self.task(self, **self.params)
  File "/home/tomw/.local/lib/python3.8/site-packages/nornir_netmiko/tasks/netmiko_send_command.py", line 26, in netmiko_send_command
    net_connect = task.host.get_connection(CONNECTION_NAME, task.nornir.config)
  File "/home/tomw/.local/lib/python3.8/site-packages/nornir/core/inventory.py", line 494, in get_connection
    self.open_connection(
  File "/home/tomw/.local/lib/python3.8/site-packages/nornir/core/inventory.py", line 546, in open_connection
    conn_obj.open(
  File "/home/tomw/.local/lib/python3.8/site-packages/nornir_netmiko/connections/netmiko.py", line 59, in open
    connection = ConnectHandler(**parameters)
  File "/home/tomw/.local/lib/python3.8/site-packages/netmiko/ssh_dispatcher.py", line 326, in ConnectHandler
    return ConnectionClass(*args, **kwargs)
  File "/home/tomw/.local/lib/python3.8/site-packages/netmiko/cisco/cisco_ios.py", line 17, in __init__
    return super().__init__(*args, **kwargs)
  File "/home/tomw/.local/lib/python3.8/site-packages/netmiko/base_connection.py", line 350, in __init__
    self._open()
  File "/home/tomw/.local/lib/python3.8/site-packages/netmiko/base_connection.py", line 355, in _open
    self.establish_connection()
  File "/home/tomw/.local/lib/python3.8/site-packages/netmiko/base_connection.py", line 957, in establish_connection
    raise NetmikoTimeoutException(msg)
netmiko.ssh_exception.NetmikoTimeoutException: TCP connection to device failed.

Common causes of this problem are:
1. Incorrect hostname or IP address.
2. Wrong TCP port.
3. Intermediate firewall blocking access.

Device settings: cisco_ios 192.168.100.103:22



2021-07-14 15:33:30,939 - nornir.core.task -    ERROR -      start() - Host 'R4': task 'netmiko_send_command' failed with traceback:
Traceback (most recent call last):
  File "/home/tomw/.local/lib/python3.8/site-packages/netmiko/base_connection.py", line 935, in establish_connection
    self.remote_conn_pre.connect(**ssh_connect_params)
  File "/home/tomw/.local/lib/python3.8/site-packages/paramiko/client.py", line 349, in connect
    retry_on_signal(lambda: sock.connect(addr))
  File "/home/tomw/.local/lib/python3.8/site-packages/paramiko/util.py", line 283, in retry_on_signal
    return function()
  File "/home/tomw/.local/lib/python3.8/site-packages/paramiko/client.py", line 349, in <lambda>
    retry_on_signal(lambda: sock.connect(addr))
socket.timeout: timed out

During handling of the above exception, another exception occurred:

Traceback (most recent call last):
  File "/home/tomw/.local/lib/python3.8/site-packages/nornir/core/task.py", line 99, in start
    r = self.task(self, **self.params)
  File "/home/tomw/.local/lib/python3.8/site-packages/nornir_netmiko/tasks/netmiko_send_command.py", line 26, in netmiko_send_command
    net_connect = task.host.get_connection(CONNECTION_NAME, task.nornir.config)
  File "/home/tomw/.local/lib/python3.8/site-packages/nornir/core/inventory.py", line 494, in get_connection
    self.open_connection(
  File "/home/tomw/.local/lib/python3.8/site-packages/nornir/core/inventory.py", line 546, in open_connection
    conn_obj.open(
  File "/home/tomw/.local/lib/python3.8/site-packages/nornir_netmiko/connections/netmiko.py", line 59, in open
    connection = ConnectHandler(**parameters)
  File "/home/tomw/.local/lib/python3.8/site-packages/netmiko/ssh_dispatcher.py", line 326, in ConnectHandler
    return ConnectionClass(*args, **kwargs)
  File "/home/tomw/.local/lib/python3.8/site-packages/netmiko/cisco/cisco_ios.py", line 17, in __init__
    return super().__init__(*args, **kwargs)
  File "/home/tomw/.local/lib/python3.8/site-packages/netmiko/base_connection.py", line 350, in __init__
    self._open()
  File "/home/tomw/.local/lib/python3.8/site-packages/netmiko/base_connection.py", line 355, in _open
    self.establish_connection()
  File "/home/tomw/.local/lib/python3.8/site-packages/netmiko/base_connection.py", line 957, in establish_connection
    raise NetmikoTimeoutException(msg)
netmiko.ssh_exception.NetmikoTimeoutException: TCP connection to device failed.

Common causes of this problem are:
1. Incorrect hostname or IP address.
2. Wrong TCP port.
3. Intermediate firewall blocking access.

Device settings: cisco_ios 192.168.100.104:22



2021-07-14 15:33:30,951 - nornir.core.task -    ERROR -      start() - Host 'R5': task 'netmiko_send_command' failed with traceback:
Traceback (most recent call last):
  File "/home/tomw/.local/lib/python3.8/site-packages/netmiko/base_connection.py", line 935, in establish_connection
    self.remote_conn_pre.connect(**ssh_connect_params)
  File "/home/tomw/.local/lib/python3.8/site-packages/paramiko/client.py", line 349, in connect
    retry_on_signal(lambda: sock.connect(addr))
  File "/home/tomw/.local/lib/python3.8/site-packages/paramiko/util.py", line 283, in retry_on_signal
    return function()
  File "/home/tomw/.local/lib/python3.8/site-packages/paramiko/client.py", line 349, in <lambda>
    retry_on_signal(lambda: sock.connect(addr))
socket.timeout: timed out

During handling of the above exception, another exception occurred:

Traceback (most recent call last):
  File "/home/tomw/.local/lib/python3.8/site-packages/nornir/core/task.py", line 99, in start
    r = self.task(self, **self.params)
  File "/home/tomw/.local/lib/python3.8/site-packages/nornir_netmiko/tasks/netmiko_send_command.py", line 26, in netmiko_send_command
    net_connect = task.host.get_connection(CONNECTION_NAME, task.nornir.config)
  File "/home/tomw/.local/lib/python3.8/site-packages/nornir/core/inventory.py", line 494, in get_connection
    self.open_connection(
  File "/home/tomw/.local/lib/python3.8/site-packages/nornir/core/inventory.py", line 546, in open_connection
    conn_obj.open(
  File "/home/tomw/.local/lib/python3.8/site-packages/nornir_netmiko/connections/netmiko.py", line 59, in open
    connection = ConnectHandler(**parameters)
  File "/home/tomw/.local/lib/python3.8/site-packages/netmiko/ssh_dispatcher.py", line 326, in ConnectHandler
    return ConnectionClass(*args, **kwargs)
  File "/home/tomw/.local/lib/python3.8/site-packages/netmiko/cisco/cisco_ios.py", line 17, in __init__
    return super().__init__(*args, **kwargs)
  File "/home/tomw/.local/lib/python3.8/site-packages/netmiko/base_connection.py", line 350, in __init__
    self._open()
  File "/home/tomw/.local/lib/python3.8/site-packages/netmiko/base_connection.py", line 355, in _open
    self.establish_connection()
  File "/home/tomw/.local/lib/python3.8/site-packages/netmiko/base_connection.py", line 957, in establish_connection
    raise NetmikoTimeoutException(msg)
netmiko.ssh_exception.NetmikoTimeoutException: TCP connection to device failed.

Common causes of this problem are:
1. Incorrect hostname or IP address.
2. Wrong TCP port.
3. Intermediate firewall blocking access.

Device settings: cisco_ios 192.168.100.105:22



2021-07-14 15:33:30,971 - nornir.core.task -    ERROR -      start() - Host 'R6': task 'netmiko_send_command' failed with traceback:
Traceback (most recent call last):
  File "/home/tomw/.local/lib/python3.8/site-packages/netmiko/base_connection.py", line 935, in establish_connection
    self.remote_conn_pre.connect(**ssh_connect_params)
  File "/home/tomw/.local/lib/python3.8/site-packages/paramiko/client.py", line 349, in connect
    retry_on_signal(lambda: sock.connect(addr))
  File "/home/tomw/.local/lib/python3.8/site-packages/paramiko/util.py", line 283, in retry_on_signal
    return function()
  File "/home/tomw/.local/lib/python3.8/site-packages/paramiko/client.py", line 349, in <lambda>
    retry_on_signal(lambda: sock.connect(addr))
socket.timeout: timed out

During handling of the above exception, another exception occurred:

Traceback (most recent call last):
  File "/home/tomw/.local/lib/python3.8/site-packages/nornir/core/task.py", line 99, in start
    r = self.task(self, **self.params)
  File "/home/tomw/.local/lib/python3.8/site-packages/nornir_netmiko/tasks/netmiko_send_command.py", line 26, in netmiko_send_command
    net_connect = task.host.get_connection(CONNECTION_NAME, task.nornir.config)
  File "/home/tomw/.local/lib/python3.8/site-packages/nornir/core/inventory.py", line 494, in get_connection
    self.open_connection(
  File "/home/tomw/.local/lib/python3.8/site-packages/nornir/core/inventory.py", line 546, in open_connection
    conn_obj.open(
  File "/home/tomw/.local/lib/python3.8/site-packages/nornir_netmiko/connections/netmiko.py", line 59, in open
    connection = ConnectHandler(**parameters)
  File "/home/tomw/.local/lib/python3.8/site-packages/netmiko/ssh_dispatcher.py", line 326, in ConnectHandler
    return ConnectionClass(*args, **kwargs)
  File "/home/tomw/.local/lib/python3.8/site-packages/netmiko/cisco/cisco_ios.py", line 17, in __init__
    return super().__init__(*args, **kwargs)
  File "/home/tomw/.local/lib/python3.8/site-packages/netmiko/base_connection.py", line 350, in __init__
    self._open()
  File "/home/tomw/.local/lib/python3.8/site-packages/netmiko/base_connection.py", line 355, in _open
    self.establish_connection()
  File "/home/tomw/.local/lib/python3.8/site-packages/netmiko/base_connection.py", line 957, in establish_connection
    raise NetmikoTimeoutException(msg)
netmiko.ssh_exception.NetmikoTimeoutException: TCP connection to device failed.

Common causes of this problem are:
1. Incorrect hostname or IP address.
2. Wrong TCP port.
3. Intermediate firewall blocking access.

Device settings: cisco_ios 192.168.100.106:22



2021-07-14 15:33:30,983 - nornir.core.task -    ERROR -      start() - Host 'R7': task 'netmiko_send_command' failed with traceback:
Traceback (most recent call last):
  File "/home/tomw/.local/lib/python3.8/site-packages/netmiko/base_connection.py", line 935, in establish_connection
    self.remote_conn_pre.connect(**ssh_connect_params)
  File "/home/tomw/.local/lib/python3.8/site-packages/paramiko/client.py", line 349, in connect
    retry_on_signal(lambda: sock.connect(addr))
  File "/home/tomw/.local/lib/python3.8/site-packages/paramiko/util.py", line 283, in retry_on_signal
    return function()
  File "/home/tomw/.local/lib/python3.8/site-packages/paramiko/client.py", line 349, in <lambda>
    retry_on_signal(lambda: sock.connect(addr))
socket.timeout: timed out

During handling of the above exception, another exception occurred:

Traceback (most recent call last):
  File "/home/tomw/.local/lib/python3.8/site-packages/nornir/core/task.py", line 99, in start
    r = self.task(self, **self.params)
  File "/home/tomw/.local/lib/python3.8/site-packages/nornir_netmiko/tasks/netmiko_send_command.py", line 26, in netmiko_send_command
    net_connect = task.host.get_connection(CONNECTION_NAME, task.nornir.config)
  File "/home/tomw/.local/lib/python3.8/site-packages/nornir/core/inventory.py", line 494, in get_connection
    self.open_connection(
  File "/home/tomw/.local/lib/python3.8/site-packages/nornir/core/inventory.py", line 546, in open_connection
    conn_obj.open(
  File "/home/tomw/.local/lib/python3.8/site-packages/nornir_netmiko/connections/netmiko.py", line 59, in open
    connection = ConnectHandler(**parameters)
  File "/home/tomw/.local/lib/python3.8/site-packages/netmiko/ssh_dispatcher.py", line 326, in ConnectHandler
    return ConnectionClass(*args, **kwargs)
  File "/home/tomw/.local/lib/python3.8/site-packages/netmiko/cisco/cisco_ios.py", line 17, in __init__
    return super().__init__(*args, **kwargs)
  File "/home/tomw/.local/lib/python3.8/site-packages/netmiko/base_connection.py", line 350, in __init__
    self._open()
  File "/home/tomw/.local/lib/python3.8/site-packages/netmiko/base_connection.py", line 355, in _open
    self.establish_connection()
  File "/home/tomw/.local/lib/python3.8/site-packages/netmiko/base_connection.py", line 957, in establish_connection
    raise NetmikoTimeoutException(msg)
netmiko.ssh_exception.NetmikoTimeoutException: TCP connection to device failed.

Common causes of this problem are:
1. Incorrect hostname or IP address.
2. Wrong TCP port.
3. Intermediate firewall blocking access.

Device settings: cisco_ios 192.168.100.107:22



2021-07-14 15:33:30,995 - nornir.core.task -    ERROR -      start() - Host 'R8': task 'netmiko_send_command' failed with traceback:
Traceback (most recent call last):
  File "/home/tomw/.local/lib/python3.8/site-packages/netmiko/base_connection.py", line 935, in establish_connection
    self.remote_conn_pre.connect(**ssh_connect_params)
  File "/home/tomw/.local/lib/python3.8/site-packages/paramiko/client.py", line 349, in connect
    retry_on_signal(lambda: sock.connect(addr))
  File "/home/tomw/.local/lib/python3.8/site-packages/paramiko/util.py", line 283, in retry_on_signal
    return function()
  File "/home/tomw/.local/lib/python3.8/site-packages/paramiko/client.py", line 349, in <lambda>
    retry_on_signal(lambda: sock.connect(addr))
socket.timeout: timed out

During handling of the above exception, another exception occurred:

Traceback (most recent call last):
  File "/home/tomw/.local/lib/python3.8/site-packages/nornir/core/task.py", line 99, in start
    r = self.task(self, **self.params)
  File "/home/tomw/.local/lib/python3.8/site-packages/nornir_netmiko/tasks/netmiko_send_command.py", line 26, in netmiko_send_command
    net_connect = task.host.get_connection(CONNECTION_NAME, task.nornir.config)
  File "/home/tomw/.local/lib/python3.8/site-packages/nornir/core/inventory.py", line 494, in get_connection
    self.open_connection(
  File "/home/tomw/.local/lib/python3.8/site-packages/nornir/core/inventory.py", line 546, in open_connection
    conn_obj.open(
  File "/home/tomw/.local/lib/python3.8/site-packages/nornir_netmiko/connections/netmiko.py", line 59, in open
    connection = ConnectHandler(**parameters)
  File "/home/tomw/.local/lib/python3.8/site-packages/netmiko/ssh_dispatcher.py", line 326, in ConnectHandler
    return ConnectionClass(*args, **kwargs)
  File "/home/tomw/.local/lib/python3.8/site-packages/netmiko/cisco/cisco_ios.py", line 17, in __init__
    return super().__init__(*args, **kwargs)
  File "/home/tomw/.local/lib/python3.8/site-packages/netmiko/base_connection.py", line 350, in __init__
    self._open()
  File "/home/tomw/.local/lib/python3.8/site-packages/netmiko/base_connection.py", line 355, in _open
    self.establish_connection()
  File "/home/tomw/.local/lib/python3.8/site-packages/netmiko/base_connection.py", line 957, in establish_connection
    raise NetmikoTimeoutException(msg)
netmiko.ssh_exception.NetmikoTimeoutException: TCP connection to device failed.

Common causes of this problem are:
1. Incorrect hostname or IP address.
2. Wrong TCP port.
3. Intermediate firewall blocking access.

Device settings: cisco_ios 192.168.100.108:22



2021-07-17 04:42:32,023 -  nornir.core -     INFO -        run() - Running task 'napalm_get' with args {'getters': ['facts', 'interfaces', 'arp_table']} on 14 hosts
2021-07-17 04:42:34,676 - nornir.core.task -    ERROR -      start() - Host 'R14': task 'napalm_get' failed with traceback:
Traceback (most recent call last):
  File "/home/tomw/.local/lib/python3.8/site-packages/netmiko/base_connection.py", line 935, in establish_connection
    self.remote_conn_pre.connect(**ssh_connect_params)
  File "/home/tomw/.local/lib/python3.8/site-packages/paramiko/client.py", line 435, in connect
    self._auth(
  File "/home/tomw/.local/lib/python3.8/site-packages/paramiko/client.py", line 764, in _auth
    raise saved_exception
  File "/home/tomw/.local/lib/python3.8/site-packages/paramiko/client.py", line 751, in _auth
    self._transport.auth_password(username, password)
  File "/home/tomw/.local/lib/python3.8/site-packages/paramiko/transport.py", line 1509, in auth_password
    return self.auth_handler.wait_for_response(my_event)
  File "/home/tomw/.local/lib/python3.8/site-packages/paramiko/auth_handler.py", line 250, in wait_for_response
    raise e
paramiko.ssh_exception.AuthenticationException: Authentication failed.

During handling of the above exception, another exception occurred:

Traceback (most recent call last):
  File "/home/tomw/.local/lib/python3.8/site-packages/nornir/core/task.py", line 99, in start
    r = self.task(self, **self.params)
  File "/home/tomw/.local/lib/python3.8/site-packages/nornir_napalm/plugins/tasks/napalm_get.py", line 32, in napalm_get
    device = task.host.get_connection(CONNECTION_NAME, task.nornir.config)
  File "/home/tomw/.local/lib/python3.8/site-packages/nornir/core/inventory.py", line 494, in get_connection
    self.open_connection(
  File "/home/tomw/.local/lib/python3.8/site-packages/nornir/core/inventory.py", line 546, in open_connection
    conn_obj.open(
  File "/home/tomw/.local/lib/python3.8/site-packages/nornir_napalm/plugins/connections/__init__.py", line 57, in open
    connection.open()
  File "/home/tomw/.local/lib/python3.8/site-packages/napalm/ios/ios.py", line 169, in open
    self.device = self._netmiko_open(
  File "/home/tomw/.local/lib/python3.8/site-packages/napalm/base/base.py", line 86, in _netmiko_open
    self._netmiko_device = ConnectHandler(
  File "/home/tomw/.local/lib/python3.8/site-packages/netmiko/ssh_dispatcher.py", line 326, in ConnectHandler
    return ConnectionClass(*args, **kwargs)
  File "/home/tomw/.local/lib/python3.8/site-packages/netmiko/cisco/cisco_ios.py", line 17, in __init__
    return super().__init__(*args, **kwargs)
  File "/home/tomw/.local/lib/python3.8/site-packages/netmiko/base_connection.py", line 350, in __init__
    self._open()
  File "/home/tomw/.local/lib/python3.8/site-packages/netmiko/base_connection.py", line 355, in _open
    self.establish_connection()
  File "/home/tomw/.local/lib/python3.8/site-packages/netmiko/base_connection.py", line 972, in establish_connection
    raise NetmikoAuthenticationException(msg)
netmiko.ssh_exception.NetmikoAuthenticationException: Authentication to device failed.

Common causes of this problem are:
1. Invalid username and password
2. Incorrect SSH-key file
3. Connecting to the wrong device

Device settings: cisco_ios 192.168.100.114:22


Authentication failed.

2021-07-17 04:42:35,095 - nornir.core.task -    ERROR -      start() - Host 'R10': task 'napalm_get' failed with traceback:
Traceback (most recent call last):
  File "/home/tomw/.local/lib/python3.8/site-packages/netmiko/base_connection.py", line 935, in establish_connection
    self.remote_conn_pre.connect(**ssh_connect_params)
  File "/home/tomw/.local/lib/python3.8/site-packages/paramiko/client.py", line 368, in connect
    raise NoValidConnectionsError(errors)
paramiko.ssh_exception.NoValidConnectionsError: [Errno None] Unable to connect to port 22 on 192.168.100.110

During handling of the above exception, another exception occurred:

Traceback (most recent call last):
  File "/home/tomw/.local/lib/python3.8/site-packages/napalm/base/base.py", line 86, in _netmiko_open
    self._netmiko_device = ConnectHandler(
  File "/home/tomw/.local/lib/python3.8/site-packages/netmiko/ssh_dispatcher.py", line 326, in ConnectHandler
    return ConnectionClass(*args, **kwargs)
  File "/home/tomw/.local/lib/python3.8/site-packages/netmiko/cisco/cisco_ios.py", line 17, in __init__
    return super().__init__(*args, **kwargs)
  File "/home/tomw/.local/lib/python3.8/site-packages/netmiko/base_connection.py", line 350, in __init__
    self._open()
  File "/home/tomw/.local/lib/python3.8/site-packages/netmiko/base_connection.py", line 355, in _open
    self.establish_connection()
  File "/home/tomw/.local/lib/python3.8/site-packages/netmiko/base_connection.py", line 957, in establish_connection
    raise NetmikoTimeoutException(msg)
netmiko.ssh_exception.NetmikoTimeoutException: TCP connection to device failed.

Common causes of this problem are:
1. Incorrect hostname or IP address.
2. Wrong TCP port.
3. Intermediate firewall blocking access.

Device settings: cisco_ios 192.168.100.110:22



During handling of the above exception, another exception occurred:

Traceback (most recent call last):
  File "/home/tomw/.local/lib/python3.8/site-packages/nornir/core/task.py", line 99, in start
    r = self.task(self, **self.params)
  File "/home/tomw/.local/lib/python3.8/site-packages/nornir_napalm/plugins/tasks/napalm_get.py", line 32, in napalm_get
    device = task.host.get_connection(CONNECTION_NAME, task.nornir.config)
  File "/home/tomw/.local/lib/python3.8/site-packages/nornir/core/inventory.py", line 494, in get_connection
    self.open_connection(
  File "/home/tomw/.local/lib/python3.8/site-packages/nornir/core/inventory.py", line 546, in open_connection
    conn_obj.open(
  File "/home/tomw/.local/lib/python3.8/site-packages/nornir_napalm/plugins/connections/__init__.py", line 57, in open
    connection.open()
  File "/home/tomw/.local/lib/python3.8/site-packages/napalm/ios/ios.py", line 169, in open
    self.device = self._netmiko_open(
  File "/home/tomw/.local/lib/python3.8/site-packages/napalm/base/base.py", line 95, in _netmiko_open
    raise ConnectionException("Cannot connect to {}".format(self.hostname))
napalm.base.exceptions.ConnectionException: Cannot connect to 192.168.100.110

2021-07-17 04:42:35,095 - nornir.core.task -    ERROR -      start() - Host 'R9': task 'napalm_get' failed with traceback:
Traceback (most recent call last):
  File "/home/tomw/.local/lib/python3.8/site-packages/netmiko/base_connection.py", line 935, in establish_connection
    self.remote_conn_pre.connect(**ssh_connect_params)
  File "/home/tomw/.local/lib/python3.8/site-packages/paramiko/client.py", line 368, in connect
    raise NoValidConnectionsError(errors)
paramiko.ssh_exception.NoValidConnectionsError: [Errno None] Unable to connect to port 22 on 192.168.100.109

During handling of the above exception, another exception occurred:

Traceback (most recent call last):
  File "/home/tomw/.local/lib/python3.8/site-packages/napalm/base/base.py", line 86, in _netmiko_open
    self._netmiko_device = ConnectHandler(
  File "/home/tomw/.local/lib/python3.8/site-packages/netmiko/ssh_dispatcher.py", line 326, in ConnectHandler
    return ConnectionClass(*args, **kwargs)
  File "/home/tomw/.local/lib/python3.8/site-packages/netmiko/cisco/cisco_ios.py", line 17, in __init__
    return super().__init__(*args, **kwargs)
  File "/home/tomw/.local/lib/python3.8/site-packages/netmiko/base_connection.py", line 350, in __init__
    self._open()
  File "/home/tomw/.local/lib/python3.8/site-packages/netmiko/base_connection.py", line 355, in _open
    self.establish_connection()
  File "/home/tomw/.local/lib/python3.8/site-packages/netmiko/base_connection.py", line 957, in establish_connection
    raise NetmikoTimeoutException(msg)
netmiko.ssh_exception.NetmikoTimeoutException: TCP connection to device failed.

Common causes of this problem are:
1. Incorrect hostname or IP address.
2. Wrong TCP port.
3. Intermediate firewall blocking access.

Device settings: cisco_ios 192.168.100.109:22



During handling of the above exception, another exception occurred:

Traceback (most recent call last):
  File "/home/tomw/.local/lib/python3.8/site-packages/nornir/core/task.py", line 99, in start
    r = self.task(self, **self.params)
  File "/home/tomw/.local/lib/python3.8/site-packages/nornir_napalm/plugins/tasks/napalm_get.py", line 32, in napalm_get
    device = task.host.get_connection(CONNECTION_NAME, task.nornir.config)
  File "/home/tomw/.local/lib/python3.8/site-packages/nornir/core/inventory.py", line 494, in get_connection
    self.open_connection(
  File "/home/tomw/.local/lib/python3.8/site-packages/nornir/core/inventory.py", line 546, in open_connection
    conn_obj.open(
  File "/home/tomw/.local/lib/python3.8/site-packages/nornir_napalm/plugins/connections/__init__.py", line 57, in open
    connection.open()
  File "/home/tomw/.local/lib/python3.8/site-packages/napalm/ios/ios.py", line 169, in open
    self.device = self._netmiko_open(
  File "/home/tomw/.local/lib/python3.8/site-packages/napalm/base/base.py", line 95, in _netmiko_open
    raise ConnectionException("Cannot connect to {}".format(self.hostname))
napalm.base.exceptions.ConnectionException: Cannot connect to 192.168.100.109

2021-07-17 04:43:48,221 -  nornir.core -     INFO -        run() - Running task 'napalm_get' with args {'getters': ['facts', 'interfaces', 'arp_table']} on 12 hosts
2021-07-17 04:43:51,038 - nornir.core.task -    ERROR -      start() - Host 'R14': task 'napalm_get' failed with traceback:
Traceback (most recent call last):
  File "/home/tomw/.local/lib/python3.8/site-packages/netmiko/base_connection.py", line 935, in establish_connection
    self.remote_conn_pre.connect(**ssh_connect_params)
  File "/home/tomw/.local/lib/python3.8/site-packages/paramiko/client.py", line 435, in connect
    self._auth(
  File "/home/tomw/.local/lib/python3.8/site-packages/paramiko/client.py", line 764, in _auth
    raise saved_exception
  File "/home/tomw/.local/lib/python3.8/site-packages/paramiko/client.py", line 751, in _auth
    self._transport.auth_password(username, password)
  File "/home/tomw/.local/lib/python3.8/site-packages/paramiko/transport.py", line 1509, in auth_password
    return self.auth_handler.wait_for_response(my_event)
  File "/home/tomw/.local/lib/python3.8/site-packages/paramiko/auth_handler.py", line 250, in wait_for_response
    raise e
paramiko.ssh_exception.AuthenticationException: Authentication failed.

During handling of the above exception, another exception occurred:

Traceback (most recent call last):
  File "/home/tomw/.local/lib/python3.8/site-packages/nornir/core/task.py", line 99, in start
    r = self.task(self, **self.params)
  File "/home/tomw/.local/lib/python3.8/site-packages/nornir_napalm/plugins/tasks/napalm_get.py", line 32, in napalm_get
    device = task.host.get_connection(CONNECTION_NAME, task.nornir.config)
  File "/home/tomw/.local/lib/python3.8/site-packages/nornir/core/inventory.py", line 494, in get_connection
    self.open_connection(
  File "/home/tomw/.local/lib/python3.8/site-packages/nornir/core/inventory.py", line 546, in open_connection
    conn_obj.open(
  File "/home/tomw/.local/lib/python3.8/site-packages/nornir_napalm/plugins/connections/__init__.py", line 57, in open
    connection.open()
  File "/home/tomw/.local/lib/python3.8/site-packages/napalm/ios/ios.py", line 169, in open
    self.device = self._netmiko_open(
  File "/home/tomw/.local/lib/python3.8/site-packages/napalm/base/base.py", line 86, in _netmiko_open
    self._netmiko_device = ConnectHandler(
  File "/home/tomw/.local/lib/python3.8/site-packages/netmiko/ssh_dispatcher.py", line 326, in ConnectHandler
    return ConnectionClass(*args, **kwargs)
  File "/home/tomw/.local/lib/python3.8/site-packages/netmiko/cisco/cisco_ios.py", line 17, in __init__
    return super().__init__(*args, **kwargs)
  File "/home/tomw/.local/lib/python3.8/site-packages/netmiko/base_connection.py", line 350, in __init__
    self._open()
  File "/home/tomw/.local/lib/python3.8/site-packages/netmiko/base_connection.py", line 355, in _open
    self.establish_connection()
  File "/home/tomw/.local/lib/python3.8/site-packages/netmiko/base_connection.py", line 972, in establish_connection
    raise NetmikoAuthenticationException(msg)
netmiko.ssh_exception.NetmikoAuthenticationException: Authentication to device failed.

Common causes of this problem are:
1. Invalid username and password
2. Incorrect SSH-key file
3. Connecting to the wrong device

Device settings: cisco_ios 192.168.100.114:22


Authentication failed.

2021-07-17 05:17:29,716 -  nornir.core -  WARNING -        run() - Task 'netmiko_send_config' has not been run – 0 hosts selected
2021-07-17 05:22:17,748 -  nornir.core -  WARNING -        run() - Task 'netmiko_send_config' has not been run – 0 hosts selected
2021-07-17 05:22:38,487 -  nornir.core -  WARNING -        run() - Task 'netmiko_send_config' has not been run – 0 hosts selected
2021-07-17 05:25:20,086 -  nornir.core -  WARNING -        run() - Task 'netmiko_send_config' has not been run – 0 hosts selected
2021-07-17 05:32:51,150 -  nornir.core -     INFO -        run() - Running task 'netmiko_send_config' with args {'config_commands': ['router ospf  10', 'mpls ldp autoconfig']} on 12 hosts
2021-07-17 05:32:53,953 - nornir.core.task -    ERROR -      start() - Host 'R14': task 'netmiko_send_config' failed with traceback:
Traceback (most recent call last):
  File "/home/tomw/.local/lib/python3.8/site-packages/netmiko/base_connection.py", line 935, in establish_connection
    self.remote_conn_pre.connect(**ssh_connect_params)
  File "/home/tomw/.local/lib/python3.8/site-packages/paramiko/client.py", line 435, in connect
    self._auth(
  File "/home/tomw/.local/lib/python3.8/site-packages/paramiko/client.py", line 764, in _auth
    raise saved_exception
  File "/home/tomw/.local/lib/python3.8/site-packages/paramiko/client.py", line 751, in _auth
    self._transport.auth_password(username, password)
  File "/home/tomw/.local/lib/python3.8/site-packages/paramiko/transport.py", line 1509, in auth_password
    return self.auth_handler.wait_for_response(my_event)
  File "/home/tomw/.local/lib/python3.8/site-packages/paramiko/auth_handler.py", line 250, in wait_for_response
    raise e
paramiko.ssh_exception.AuthenticationException: Authentication failed.

During handling of the above exception, another exception occurred:

Traceback (most recent call last):
  File "/home/tomw/.local/lib/python3.8/site-packages/nornir/core/task.py", line 99, in start
    r = self.task(self, **self.params)
  File "/home/tomw/.local/lib/python3.8/site-packages/nornir_netmiko/tasks/netmiko_send_config.py", line 24, in netmiko_send_config
    net_connect = task.host.get_connection(CONNECTION_NAME, task.nornir.config)
  File "/home/tomw/.local/lib/python3.8/site-packages/nornir/core/inventory.py", line 494, in get_connection
    self.open_connection(
  File "/home/tomw/.local/lib/python3.8/site-packages/nornir/core/inventory.py", line 546, in open_connection
    conn_obj.open(
  File "/home/tomw/.local/lib/python3.8/site-packages/nornir_netmiko/connections/netmiko.py", line 59, in open
    connection = ConnectHandler(**parameters)
  File "/home/tomw/.local/lib/python3.8/site-packages/netmiko/ssh_dispatcher.py", line 326, in ConnectHandler
    return ConnectionClass(*args, **kwargs)
  File "/home/tomw/.local/lib/python3.8/site-packages/netmiko/cisco/cisco_ios.py", line 17, in __init__
    return super().__init__(*args, **kwargs)
  File "/home/tomw/.local/lib/python3.8/site-packages/netmiko/base_connection.py", line 350, in __init__
    self._open()
  File "/home/tomw/.local/lib/python3.8/site-packages/netmiko/base_connection.py", line 355, in _open
    self.establish_connection()
  File "/home/tomw/.local/lib/python3.8/site-packages/netmiko/base_connection.py", line 972, in establish_connection
    raise NetmikoAuthenticationException(msg)
netmiko.ssh_exception.NetmikoAuthenticationException: Authentication to device failed.

Common causes of this problem are:
1. Invalid username and password
2. Incorrect SSH-key file
3. Connecting to the wrong device

Device settings: cisco_ios 192.168.100.114:22


Authentication failed.

2021-07-17 05:35:20,127 -  nornir.core -     INFO -        run() - Running task 'netmiko_send_config' with args {'config_commands': ['do wr']} on 12 hosts
2021-07-17 05:35:22,843 - nornir.core.task -    ERROR -      start() - Host 'R14': task 'netmiko_send_config' failed with traceback:
Traceback (most recent call last):
  File "/home/tomw/.local/lib/python3.8/site-packages/netmiko/base_connection.py", line 935, in establish_connection
    self.remote_conn_pre.connect(**ssh_connect_params)
  File "/home/tomw/.local/lib/python3.8/site-packages/paramiko/client.py", line 435, in connect
    self._auth(
  File "/home/tomw/.local/lib/python3.8/site-packages/paramiko/client.py", line 764, in _auth
    raise saved_exception
  File "/home/tomw/.local/lib/python3.8/site-packages/paramiko/client.py", line 751, in _auth
    self._transport.auth_password(username, password)
  File "/home/tomw/.local/lib/python3.8/site-packages/paramiko/transport.py", line 1509, in auth_password
    return self.auth_handler.wait_for_response(my_event)
  File "/home/tomw/.local/lib/python3.8/site-packages/paramiko/auth_handler.py", line 250, in wait_for_response
    raise e
paramiko.ssh_exception.AuthenticationException: Authentication failed.

During handling of the above exception, another exception occurred:

Traceback (most recent call last):
  File "/home/tomw/.local/lib/python3.8/site-packages/nornir/core/task.py", line 99, in start
    r = self.task(self, **self.params)
  File "/home/tomw/.local/lib/python3.8/site-packages/nornir_netmiko/tasks/netmiko_send_config.py", line 24, in netmiko_send_config
    net_connect = task.host.get_connection(CONNECTION_NAME, task.nornir.config)
  File "/home/tomw/.local/lib/python3.8/site-packages/nornir/core/inventory.py", line 494, in get_connection
    self.open_connection(
  File "/home/tomw/.local/lib/python3.8/site-packages/nornir/core/inventory.py", line 546, in open_connection
    conn_obj.open(
  File "/home/tomw/.local/lib/python3.8/site-packages/nornir_netmiko/connections/netmiko.py", line 59, in open
    connection = ConnectHandler(**parameters)
  File "/home/tomw/.local/lib/python3.8/site-packages/netmiko/ssh_dispatcher.py", line 326, in ConnectHandler
    return ConnectionClass(*args, **kwargs)
  File "/home/tomw/.local/lib/python3.8/site-packages/netmiko/cisco/cisco_ios.py", line 17, in __init__
    return super().__init__(*args, **kwargs)
  File "/home/tomw/.local/lib/python3.8/site-packages/netmiko/base_connection.py", line 350, in __init__
    self._open()
  File "/home/tomw/.local/lib/python3.8/site-packages/netmiko/base_connection.py", line 355, in _open
    self.establish_connection()
  File "/home/tomw/.local/lib/python3.8/site-packages/netmiko/base_connection.py", line 972, in establish_connection
    raise NetmikoAuthenticationException(msg)
netmiko.ssh_exception.NetmikoAuthenticationException: Authentication to device failed.

Common causes of this problem are:
1. Invalid username and password
2. Incorrect SSH-key file
3. Connecting to the wrong device

Device settings: cisco_ios 192.168.100.114:22


Authentication failed.

2021-07-17 05:41:05,207 -  nornir.core -  WARNING -        run() - Task 'netmiko_send_config' has not been run – 0 hosts selected
2021-07-17 05:42:25,688 -  nornir.core -  WARNING -        run() - Task 'netmiko_send_config' has not been run – 0 hosts selected
2021-07-17 05:42:37,028 -  nornir.core -  WARNING -        run() - Task 'netmiko_send_config' has not been run – 0 hosts selected
2021-07-17 05:42:56,984 -  nornir.core -  WARNING -        run() - Task 'netmiko_send_config' has not been run – 0 hosts selected
2021-07-17 05:44:48,321 -  nornir.core -     INFO -        run() - Running task 'netmiko_send_config' with args {'config_commands': ['do wr']} on 12 hosts
2021-07-17 05:44:50,951 - nornir.core.task -    ERROR -      start() - Host 'R14': task 'netmiko_send_config' failed with traceback:
Traceback (most recent call last):
  File "/home/tomw/.local/lib/python3.8/site-packages/netmiko/base_connection.py", line 935, in establish_connection
    self.remote_conn_pre.connect(**ssh_connect_params)
  File "/home/tomw/.local/lib/python3.8/site-packages/paramiko/client.py", line 435, in connect
    self._auth(
  File "/home/tomw/.local/lib/python3.8/site-packages/paramiko/client.py", line 764, in _auth
    raise saved_exception
  File "/home/tomw/.local/lib/python3.8/site-packages/paramiko/client.py", line 751, in _auth
    self._transport.auth_password(username, password)
  File "/home/tomw/.local/lib/python3.8/site-packages/paramiko/transport.py", line 1509, in auth_password
    return self.auth_handler.wait_for_response(my_event)
  File "/home/tomw/.local/lib/python3.8/site-packages/paramiko/auth_handler.py", line 250, in wait_for_response
    raise e
paramiko.ssh_exception.AuthenticationException: Authentication failed.

During handling of the above exception, another exception occurred:

Traceback (most recent call last):
  File "/home/tomw/.local/lib/python3.8/site-packages/nornir/core/task.py", line 99, in start
    r = self.task(self, **self.params)
  File "/home/tomw/.local/lib/python3.8/site-packages/nornir_netmiko/tasks/netmiko_send_config.py", line 24, in netmiko_send_config
    net_connect = task.host.get_connection(CONNECTION_NAME, task.nornir.config)
  File "/home/tomw/.local/lib/python3.8/site-packages/nornir/core/inventory.py", line 494, in get_connection
    self.open_connection(
  File "/home/tomw/.local/lib/python3.8/site-packages/nornir/core/inventory.py", line 546, in open_connection
    conn_obj.open(
  File "/home/tomw/.local/lib/python3.8/site-packages/nornir_netmiko/connections/netmiko.py", line 59, in open
    connection = ConnectHandler(**parameters)
  File "/home/tomw/.local/lib/python3.8/site-packages/netmiko/ssh_dispatcher.py", line 326, in ConnectHandler
    return ConnectionClass(*args, **kwargs)
  File "/home/tomw/.local/lib/python3.8/site-packages/netmiko/cisco/cisco_ios.py", line 17, in __init__
    return super().__init__(*args, **kwargs)
  File "/home/tomw/.local/lib/python3.8/site-packages/netmiko/base_connection.py", line 350, in __init__
    self._open()
  File "/home/tomw/.local/lib/python3.8/site-packages/netmiko/base_connection.py", line 355, in _open
    self.establish_connection()
  File "/home/tomw/.local/lib/python3.8/site-packages/netmiko/base_connection.py", line 972, in establish_connection
    raise NetmikoAuthenticationException(msg)
netmiko.ssh_exception.NetmikoAuthenticationException: Authentication to device failed.

Common causes of this problem are:
1. Invalid username and password
2. Incorrect SSH-key file
3. Connecting to the wrong device

Device settings: cisco_ios 192.168.100.114:22


Authentication failed.

2021-07-17 05:45:32,165 -  nornir.core -  WARNING -        run() - Task 'netmiko_send_config' has not been run – 0 hosts selected
2021-07-17 05:45:41,987 -  nornir.core -     INFO -        run() - Running task 'netmiko_send_config' with args {'config_commands': ['do wr']} on 12 hosts
2021-07-17 05:45:44,788 - nornir.core.task -    ERROR -      start() - Host 'R14': task 'netmiko_send_config' failed with traceback:
Traceback (most recent call last):
  File "/home/tomw/.local/lib/python3.8/site-packages/netmiko/base_connection.py", line 935, in establish_connection
    self.remote_conn_pre.connect(**ssh_connect_params)
  File "/home/tomw/.local/lib/python3.8/site-packages/paramiko/client.py", line 435, in connect
    self._auth(
  File "/home/tomw/.local/lib/python3.8/site-packages/paramiko/client.py", line 764, in _auth
    raise saved_exception
  File "/home/tomw/.local/lib/python3.8/site-packages/paramiko/client.py", line 751, in _auth
    self._transport.auth_password(username, password)
  File "/home/tomw/.local/lib/python3.8/site-packages/paramiko/transport.py", line 1509, in auth_password
    return self.auth_handler.wait_for_response(my_event)
  File "/home/tomw/.local/lib/python3.8/site-packages/paramiko/auth_handler.py", line 250, in wait_for_response
    raise e
paramiko.ssh_exception.AuthenticationException: Authentication failed.

During handling of the above exception, another exception occurred:

Traceback (most recent call last):
  File "/home/tomw/.local/lib/python3.8/site-packages/nornir/core/task.py", line 99, in start
    r = self.task(self, **self.params)
  File "/home/tomw/.local/lib/python3.8/site-packages/nornir_netmiko/tasks/netmiko_send_config.py", line 24, in netmiko_send_config
    net_connect = task.host.get_connection(CONNECTION_NAME, task.nornir.config)
  File "/home/tomw/.local/lib/python3.8/site-packages/nornir/core/inventory.py", line 494, in get_connection
    self.open_connection(
  File "/home/tomw/.local/lib/python3.8/site-packages/nornir/core/inventory.py", line 546, in open_connection
    conn_obj.open(
  File "/home/tomw/.local/lib/python3.8/site-packages/nornir_netmiko/connections/netmiko.py", line 59, in open
    connection = ConnectHandler(**parameters)
  File "/home/tomw/.local/lib/python3.8/site-packages/netmiko/ssh_dispatcher.py", line 326, in ConnectHandler
    return ConnectionClass(*args, **kwargs)
  File "/home/tomw/.local/lib/python3.8/site-packages/netmiko/cisco/cisco_ios.py", line 17, in __init__
    return super().__init__(*args, **kwargs)
  File "/home/tomw/.local/lib/python3.8/site-packages/netmiko/base_connection.py", line 350, in __init__
    self._open()
  File "/home/tomw/.local/lib/python3.8/site-packages/netmiko/base_connection.py", line 355, in _open
    self.establish_connection()
  File "/home/tomw/.local/lib/python3.8/site-packages/netmiko/base_connection.py", line 972, in establish_connection
    raise NetmikoAuthenticationException(msg)
netmiko.ssh_exception.NetmikoAuthenticationException: Authentication to device failed.

Common causes of this problem are:
1. Invalid username and password
2. Incorrect SSH-key file
3. Connecting to the wrong device

Device settings: cisco_ios 192.168.100.114:22


Authentication failed.

2021-07-17 05:46:28,443 -  nornir.core -     INFO -        run() - Running task 'netmiko_send_config' with args {'config_commands': ['do wr']} on 12 hosts
2021-07-17 05:46:31,080 - nornir.core.task -    ERROR -      start() - Host 'R14': task 'netmiko_send_config' failed with traceback:
Traceback (most recent call last):
  File "/home/tomw/.local/lib/python3.8/site-packages/netmiko/base_connection.py", line 935, in establish_connection
    self.remote_conn_pre.connect(**ssh_connect_params)
  File "/home/tomw/.local/lib/python3.8/site-packages/paramiko/client.py", line 435, in connect
    self._auth(
  File "/home/tomw/.local/lib/python3.8/site-packages/paramiko/client.py", line 764, in _auth
    raise saved_exception
  File "/home/tomw/.local/lib/python3.8/site-packages/paramiko/client.py", line 751, in _auth
    self._transport.auth_password(username, password)
  File "/home/tomw/.local/lib/python3.8/site-packages/paramiko/transport.py", line 1509, in auth_password
    return self.auth_handler.wait_for_response(my_event)
  File "/home/tomw/.local/lib/python3.8/site-packages/paramiko/auth_handler.py", line 250, in wait_for_response
    raise e
paramiko.ssh_exception.AuthenticationException: Authentication failed.

During handling of the above exception, another exception occurred:

Traceback (most recent call last):
  File "/home/tomw/.local/lib/python3.8/site-packages/nornir/core/task.py", line 99, in start
    r = self.task(self, **self.params)
  File "/home/tomw/.local/lib/python3.8/site-packages/nornir_netmiko/tasks/netmiko_send_config.py", line 24, in netmiko_send_config
    net_connect = task.host.get_connection(CONNECTION_NAME, task.nornir.config)
  File "/home/tomw/.local/lib/python3.8/site-packages/nornir/core/inventory.py", line 494, in get_connection
    self.open_connection(
  File "/home/tomw/.local/lib/python3.8/site-packages/nornir/core/inventory.py", line 546, in open_connection
    conn_obj.open(
  File "/home/tomw/.local/lib/python3.8/site-packages/nornir_netmiko/connections/netmiko.py", line 59, in open
    connection = ConnectHandler(**parameters)
  File "/home/tomw/.local/lib/python3.8/site-packages/netmiko/ssh_dispatcher.py", line 326, in ConnectHandler
    return ConnectionClass(*args, **kwargs)
  File "/home/tomw/.local/lib/python3.8/site-packages/netmiko/cisco/cisco_ios.py", line 17, in __init__
    return super().__init__(*args, **kwargs)
  File "/home/tomw/.local/lib/python3.8/site-packages/netmiko/base_connection.py", line 350, in __init__
    self._open()
  File "/home/tomw/.local/lib/python3.8/site-packages/netmiko/base_connection.py", line 355, in _open
    self.establish_connection()
  File "/home/tomw/.local/lib/python3.8/site-packages/netmiko/base_connection.py", line 972, in establish_connection
    raise NetmikoAuthenticationException(msg)
netmiko.ssh_exception.NetmikoAuthenticationException: Authentication to device failed.

Common causes of this problem are:
1. Invalid username and password
2. Incorrect SSH-key file
3. Connecting to the wrong device

Device settings: cisco_ios 192.168.100.114:22


Authentication failed.

2021-07-17 05:48:50,389 -  nornir.core -     INFO -        run() - Running task 'netmiko_send_config' with args {'config_commands': ['do wr']} on 12 hosts
2021-07-17 05:48:53,051 - nornir.core.task -    ERROR -      start() - Host 'R14': task 'netmiko_send_config' failed with traceback:
Traceback (most recent call last):
  File "/home/tomw/.local/lib/python3.8/site-packages/netmiko/base_connection.py", line 935, in establish_connection
    self.remote_conn_pre.connect(**ssh_connect_params)
  File "/home/tomw/.local/lib/python3.8/site-packages/paramiko/client.py", line 435, in connect
    self._auth(
  File "/home/tomw/.local/lib/python3.8/site-packages/paramiko/client.py", line 764, in _auth
    raise saved_exception
  File "/home/tomw/.local/lib/python3.8/site-packages/paramiko/client.py", line 751, in _auth
    self._transport.auth_password(username, password)
  File "/home/tomw/.local/lib/python3.8/site-packages/paramiko/transport.py", line 1509, in auth_password
    return self.auth_handler.wait_for_response(my_event)
  File "/home/tomw/.local/lib/python3.8/site-packages/paramiko/auth_handler.py", line 250, in wait_for_response
    raise e
paramiko.ssh_exception.AuthenticationException: Authentication failed.

During handling of the above exception, another exception occurred:

Traceback (most recent call last):
  File "/home/tomw/.local/lib/python3.8/site-packages/nornir/core/task.py", line 99, in start
    r = self.task(self, **self.params)
  File "/home/tomw/.local/lib/python3.8/site-packages/nornir_netmiko/tasks/netmiko_send_config.py", line 24, in netmiko_send_config
    net_connect = task.host.get_connection(CONNECTION_NAME, task.nornir.config)
  File "/home/tomw/.local/lib/python3.8/site-packages/nornir/core/inventory.py", line 494, in get_connection
    self.open_connection(
  File "/home/tomw/.local/lib/python3.8/site-packages/nornir/core/inventory.py", line 546, in open_connection
    conn_obj.open(
  File "/home/tomw/.local/lib/python3.8/site-packages/nornir_netmiko/connections/netmiko.py", line 59, in open
    connection = ConnectHandler(**parameters)
  File "/home/tomw/.local/lib/python3.8/site-packages/netmiko/ssh_dispatcher.py", line 326, in ConnectHandler
    return ConnectionClass(*args, **kwargs)
  File "/home/tomw/.local/lib/python3.8/site-packages/netmiko/cisco/cisco_ios.py", line 17, in __init__
    return super().__init__(*args, **kwargs)
  File "/home/tomw/.local/lib/python3.8/site-packages/netmiko/base_connection.py", line 350, in __init__
    self._open()
  File "/home/tomw/.local/lib/python3.8/site-packages/netmiko/base_connection.py", line 355, in _open
    self.establish_connection()
  File "/home/tomw/.local/lib/python3.8/site-packages/netmiko/base_connection.py", line 972, in establish_connection
    raise NetmikoAuthenticationException(msg)
netmiko.ssh_exception.NetmikoAuthenticationException: Authentication to device failed.

Common causes of this problem are:
1. Invalid username and password
2. Incorrect SSH-key file
3. Connecting to the wrong device

Device settings: cisco_ios 192.168.100.114:22


Authentication failed.

2021-07-17 05:49:07,688 -  nornir.core -  WARNING -        run() - Task 'netmiko_send_config' has not been run – 0 hosts selected
2021-07-17 05:49:31,453 -  nornir.core -  WARNING -        run() - Task 'netmiko_send_config' has not been run – 0 hosts selected
